<?xml version="1.0" ?>
<!-- =================================================================================== -->
<!-- |    This document was autogenerated by xacro from mobile.xacro                   | -->
<!-- |    EDITING THIS FILE BY HAND IS NOT RECOMMENDED                                 | -->
<!-- =================================================================================== -->
<robot name="mobile">
  <material name="silver">
    <color rgba="0.700 0.700 0.700 1.000"/>
  </material>
  <transmission name="Revolute 1_tran">
    <type>transmission_interface/SimpleTransmission</type>
    <joint name="Revolute 1">
      <hardwareInterface>hardware_interface/EffortJointInterface</hardwareInterface>
    </joint>
    <actuator name="Revolute 1_actr">
      <hardwareInterface>hardware_interface/EffortJointInterface</hardwareInterface>
      <mechanicalReduction>1</mechanicalReduction>
    </actuator>
  </transmission>
  <transmission name="Revolute 2_tran">
    <type>transmission_interface/SimpleTransmission</type>
    <joint name="Revolute 2">
      <hardwareInterface>hardware_interface/EffortJointInterface</hardwareInterface>
    </joint>
    <actuator name="Revolute 2_actr">
      <hardwareInterface>hardware_interface/EffortJointInterface</hardwareInterface>
      <mechanicalReduction>1</mechanicalReduction>
    </actuator>
  </transmission>
  <transmission name="Revolute 3_tran">
    <type>transmission_interface/SimpleTransmission</type>
    <joint name="Revolute 3">
      <hardwareInterface>hardware_interface/EffortJointInterface</hardwareInterface>
    </joint>
    <actuator name="Revolute 3_actr">
      <hardwareInterface>hardware_interface/EffortJointInterface</hardwareInterface>
      <mechanicalReduction>1</mechanicalReduction>
    </actuator>
  </transmission>
  <transmission name="Revolute 4_tran">
    <type>transmission_interface/SimpleTransmission</type>
    <joint name="Revolute 4">
      <hardwareInterface>hardware_interface/EffortJointInterface</hardwareInterface>
    </joint>
    <actuator name="Revolute 4_actr">
      <hardwareInterface>hardware_interface/EffortJointInterface</hardwareInterface>
      <mechanicalReduction>1</mechanicalReduction>
    </actuator>
  </transmission>
  <gazebo>
    <plugin filename="libgazebo_ros_control.so" name="control"/>
  </gazebo>
  <gazebo reference="base_link">
    <material>Gazebo/Silver</material>
    <mu1>0.2</mu1>
    <mu2>0.2</mu2>
    <self_collide>true</self_collide>
    <gravity>true</gravity>
  </gazebo>
  <gazebo reference="rear_right_wheel_1">
    <material>Gazebo/Silver</material>
    <mu1>0.2</mu1>
    <mu2>0.2</mu2>
    <self_collide>true</self_collide>
  </gazebo>
  <gazebo reference="front_right_wheel_1">
    <material>Gazebo/Silver</material>
    <mu1>0.2</mu1>
    <mu2>0.2</mu2>
    <self_collide>true</self_collide>
  </gazebo>
  <gazebo reference="front_left_wheel_1">
    <material>Gazebo/Silver</material>
    <mu1>0.2</mu1>
    <mu2>0.2</mu2>
    <self_collide>true</self_collide>
  </gazebo>
  <gazebo reference="rear_left_wheel_1">
    <material>Gazebo/Silver</material>
    <mu1>0.2</mu1>
    <mu2>0.2</mu2>
    <self_collide>true</self_collide>
  </gazebo>
  <gazebo reference="lidar_1">
    <material>Gazebo/Silver</material>
    <mu1>0.2</mu1>
    <mu2>0.2</mu2>
    <self_collide>true</self_collide>
  </gazebo>
  <gazebo reference="imu_1">
    <material>Gazebo/Silver</material>
    <mu1>0.2</mu1>
    <mu2>0.2</mu2>
    <self_collide>true</self_collide>
  </gazebo>
  <link name="base_link">
    <inertial>
      <origin rpy="0 0 0" xyz="0.004366302399893529 -4.78586553112421e-16 0.1724423094093739"/>
      <mass value="50.124334037291106"/>
      <inertia ixx="0.739222" ixy="0.0" ixz="-0.031779" iyy="1.189387" iyz="-0.0" izz="1.325001"/>
    </inertial>
    <visual>
      <origin rpy="0 0 0" xyz="0 0 0"/>
      <geometry>
        <mesh filename="file:///home/ohj/mecanum-ros2/install/mobile_description/share/mobile_description/meshes/base_link.stl" scale="0.001 0.001 0.001"/>
      </geometry>
      <material name="silver"/>
    </visual>
    <collision>
      <origin rpy="0 0 0" xyz="0 0 0"/>
      <geometry>
        <mesh filename="file:///home/ohj/mecanum-ros2/install/mobile_description/share/mobile_description/meshes/base_link.stl" scale="0.001 0.001 0.001"/>
      </geometry>
    </collision>
  </link>
  <link name="front_left_link">
    <inertial>
      <origin rpy="0 0 0" xyz="-9.631184738623233e-15 -0.01999999999999999 0.0"/>
      <mass value="3.8533597391687295"/>
      <inertia ixx="0.004277" ixy="-0.0" ixz="0.0" iyy="0.007526" iyz="0.0" izz="0.004277"/>
    </inertial>
    <visual>
      <origin rpy="0 0 0" xyz="0.145 0.17 -0.0625"/>
      <geometry>
        <mesh filename="file:///home/ohj/mecanum-ros2/install/mobile_description/share/mobile_description/meshes/rear_right_wheel_1.stl" scale="0.001 0.001 0.001"/>
      </geometry>
      <material name="silver"/>
    </visual>
    <collision>
      <origin rpy="0 0 0" xyz="0.145 0.17 -0.0625"/>
      <geometry>
        <mesh filename="file:///home/ohj/mecanum-ros2/install/mobile_description/share/mobile_description/meshes/rear_right_wheel_1.stl" scale="0.001 0.001 0.001"/>
      </geometry>
    </collision>
  </link>
  <link name="rear_left_link">
    <inertial>
      <origin rpy="0 0 0" xyz="9.742207041085749e-15 -0.01999999999999999 1.3877787807814457e-17"/>
      <mass value="3.8533597391687295"/>
      <inertia ixx="0.004277" ixy="-0.0" ixz="0.0" iyy="0.007526" iyz="-0.0" izz="0.004277"/>
    </inertial>
    <visual>
      <origin rpy="0 0 0" xyz="-0.145 0.17 -0.0625"/>
      <geometry>
        <mesh filename="file:///home/ohj/mecanum-ros2/install/mobile_description/share/mobile_description/meshes/front_right_wheel_1.stl" scale="0.001 0.001 0.001"/>
      </geometry>
      <material name="silver"/>
    </visual>
    <collision>
      <origin rpy="0 0 0" xyz="-0.145 0.17 -0.0625"/>
      <geometry>
        <mesh filename="file:///home/ohj/mecanum-ros2/install/mobile_description/share/mobile_description/meshes/front_right_wheel_1.stl" scale="0.001 0.001 0.001"/>
      </geometry>
    </collision>
  </link>
  <link name="rear_right_link">
    <inertial>
      <origin rpy="0 0 0" xyz="2.7755575615628914e-17 0.019999999999999962 0.0"/>
      <mass value="3.8533597391687295"/>
      <inertia ixx="0.004277" ixy="-0.0" ixz="0.0" iyy="0.007526" iyz="-0.0" izz="0.004277"/>
    </inertial>
    <visual>
      <origin rpy="0 0 0" xyz="-0.145 -0.17 -0.0625"/>
      <geometry>
        <mesh filename="file:///home/ohj/mecanum-ros2/install/mobile_description/share/mobile_description/meshes/front_left_wheel_1.stl" scale="0.001 0.001 0.001"/>
      </geometry>
      <material name="silver"/>
    </visual>
    <collision>
      <origin rpy="0 0 0" xyz="-0.145 -0.17 -0.0625"/>
      <geometry>
        <mesh filename="file:///home/ohj/mecanum-ros2/install/mobile_description/share/mobile_description/meshes/front_left_wheel_1.stl" scale="0.001 0.001 0.001"/>
      </geometry>
    </collision>
  </link>
  <link name="front_right_link">
    <inertial>
      <origin rpy="0 0 0" xyz="-5.551115123125783e-17 0.019999999999999962 0.0"/>
      <mass value="3.8533597391687295"/>
      <inertia ixx="0.004277" ixy="-0.0" ixz="-0.0" iyy="0.007526" iyz="-0.0" izz="0.004277"/>
    </inertial>
    <visual>
      <origin rpy="0 0 0" xyz="0.145 -0.17 -0.0625"/>
      <geometry>
        <mesh filename="file:///home/ohj/mecanum-ros2/install/mobile_description/share/mobile_description/meshes/rear_left_wheel_1.stl" scale="0.001 0.001 0.001"/>
      </geometry>
      <material name="silver"/>
    </visual>
    <collision>
      <origin rpy="0 0 0" xyz="0.145 -0.17 -0.0625"/>
      <geometry>
        <mesh filename="file:///home/ohj/mecanum-ros2/install/mobile_description/share/mobile_description/meshes/rear_left_wheel_1.stl" scale="0.001 0.001 0.001"/>
      </geometry>
    </collision>
  </link>
  <link name="lidar_link">
    <inertial>
      <origin rpy="0 0 0" xyz="-9.4946098205817e-10 6.800340879809758e-16 0.019779238971984525"/>
      <mass value="1.1942370825491377"/>
      <inertia ixx="0.000518" ixy="-0.0" ixz="-0.0" iyy="0.000518" iyz="-0.0" izz="0.000724"/>
    </inertial>
    <visual>
      <origin rpy="0 0 0" xyz="-0.205 -0.0 -0.3275"/>
      <geometry>
        <mesh filename="file:///home/ohj/mecanum-ros2/install/mobile_description/share/mobile_description/meshes/lidar_1.stl" scale="0.001 0.001 0.001"/>
      </geometry>
      <material name="silver"/>
    </visual>
    <collision>
      <origin rpy="0 0 0" xyz="-0.205 -0.0 -0.3275"/>
      <geometry>
        <mesh filename="file:///home/ohj/mecanum-ros2/install/mobile_description/share/mobile_description/meshes/lidar_1.stl" scale="0.001 0.001 0.001"/>
      </geometry>
    </collision>
  </link>
  <link name="imu_link">
    <inertial>
      <origin rpy="0 0 0" xyz="0.0 0.0 0.0050000000000000044"/>
      <mass value="0.07064999999999999"/>
      <inertia ixx="6e-06" ixy="0.0" ixz="0.0" iyy="6e-06" iyz="0.0" izz="1.1e-05"/>
    </inertial>
    <visual>
      <origin rpy="0 0 0" xyz="-0.0 -0.0 -0.3275"/>
      <geometry>
        <mesh filename="file:///home/ohj/mecanum-ros2/install/mobile_description/share/mobile_description/meshes/imu_1.stl" scale="0.001 0.001 0.001"/>
      </geometry>
      <material name="silver"/>
    </visual>
    <collision>
      <origin rpy="0 0 0" xyz="-0.0 -0.0 -0.3275"/>
      <geometry>
        <mesh filename="file:///home/ohj/mecanum-ros2/install/mobile_description/share/mobile_description/meshes/imu_1.stl" scale="0.001 0.001 0.001"/>
      </geometry>
    </collision>
  </link>
  <joint name="rear_right_joint" type="continuous">
    <origin rpy="0 0 0" xyz="-0.145 -0.17 0.0625"/>
    <parent link="base_link"/>
    <child link="rear_right_link"/>
    <axis xyz="0.0 -1.0 0.0"/>
  </joint>
  <joint name="front_right_joint" type="continuous">
    <origin rpy="0 0 0" xyz="0.145 -0.17 0.0625"/>
    <parent link="base_link"/>
    <child link="front_right_link"/>
    <axis xyz="0.0 -1.0 0.0"/>
  </joint>
  <joint name="front_left_joint" type="continuous">
    <origin rpy="0 0 0" xyz="0.145 0.17 0.0625"/>
    <parent link="base_link"/>
    <child link="front_left_link"/>
    <axis xyz="0.0 1.0 0.0"/>
  </joint>
  <joint name="rear_left_joint" type="continuous">
    <origin rpy="0 0 0" xyz="-0.145 0.17 0.0625"/>
    <parent link="base_link"/>
    <child link="rear_left_link"/>
    <axis xyz="0.0 1.0 0.0"/>
  </joint>
  <joint name="lidar_joint" type="fixed">
    <origin rpy="0 0 0" xyz="0.205 0.0 0.3275"/>
    <parent link="base_link"/>
    <child link="lidar_link"/>
  </joint>
  <joint name="imu_joint" type="fixed">
    <origin rpy="0 0 0" xyz="0.0 0.0 0.3275"/>
    <parent link="base_link"/>
    <child link="imu_link"/>
  </joint>
</robot>
