<?xml version="1.0" ?>
<robot name="mobile" xmlns:xacro="http://www.ros.org/wiki/xacro">

<xacro:include filename="$(find mobile_description)/urdf/materials.xacro" />
<xacro:include filename="$(find mobile_description)/urdf/mobile.trans" />
<xacro:include filename="$(find mobile_description)/urdf/mobile.gazebo" />
<link name="base_link">
  <inertial>
    <origin xyz="0.004366302399893529 -4.78586553112421e-16 0.1724423094093739" rpy="0 0 0"/>
    <mass value="50.124334037291106"/>
    <inertia ixx="0.739222" iyy="1.189387" izz="1.325001" ixy="0.0" iyz="-0.0" ixz="-0.031779"/>
  </inertial>
  <visual>
    <origin xyz="0 0 0" rpy="0 0 0"/>
    <geometry>
      <mesh filename="package://mobile_description/meshes/base_link.stl" scale="0.001 0.001 0.001"/>
    </geometry>
    <material name="silver"/>
  </visual>
  <collision>
    <origin xyz="0 0 0" rpy="0 0 0"/>
    <geometry>
      <mesh filename="package://mobile_description/meshes/base_link.stl" scale="0.001 0.001 0.001"/>
    </geometry>
  </collision>
</link>

<link name="rear_right_wheel_1">
  <inertial>
    <origin xyz="-9.631184738623233e-15 -0.01999999999999999 0.0" rpy="0 0 0"/>
    <mass value="3.8533597391687295"/>
    <inertia ixx="0.004277" iyy="0.007526" izz="0.004277" ixy="-0.0" iyz="0.0" ixz="0.0"/>
  </inertial>
  <visual>
    <origin xyz="0.145 0.17 -0.0625" rpy="0 0 0"/>
    <geometry>
      <mesh filename="package://mobile_description/meshes/rear_right_wheel_1.stl" scale="0.001 0.001 0.001"/>
    </geometry>
    <material name="silver"/>
  </visual>
  <collision>
    <origin xyz="0.145 0.17 -0.0625" rpy="0 0 0"/>
    <geometry>
      <mesh filename="package://mobile_description/meshes/rear_right_wheel_1.stl" scale="0.001 0.001 0.001"/>
    </geometry>
  </collision>
</link>

<link name="front_right_wheel_1">
  <inertial>
    <origin xyz="9.742207041085749e-15 -0.01999999999999999 1.3877787807814457e-17" rpy="0 0 0"/>
    <mass value="3.8533597391687295"/>
    <inertia ixx="0.004277" iyy="0.007526" izz="0.004277" ixy="-0.0" iyz="-0.0" ixz="0.0"/>
  </inertial>
  <visual>
    <origin xyz="-0.145 0.17 -0.0625" rpy="0 0 0"/>
    <geometry>
      <mesh filename="package://mobile_description/meshes/front_right_wheel_1.stl" scale="0.001 0.001 0.001"/>
    </geometry>
    <material name="silver"/>
  </visual>
  <collision>
    <origin xyz="-0.145 0.17 -0.0625" rpy="0 0 0"/>
    <geometry>
      <mesh filename="package://mobile_description/meshes/front_right_wheel_1.stl" scale="0.001 0.001 0.001"/>
    </geometry>
  </collision>
</link>

<link name="front_left_wheel_1">
  <inertial>
    <origin xyz="2.7755575615628914e-17 0.019999999999999962 0.0" rpy="0 0 0"/>
    <mass value="3.8533597391687295"/>
    <inertia ixx="0.004277" iyy="0.007526" izz="0.004277" ixy="-0.0" iyz="-0.0" ixz="0.0"/>
  </inertial>
  <visual>
    <origin xyz="-0.145 -0.17 -0.0625" rpy="0 0 0"/>
    <geometry>
      <mesh filename="package://mobile_description/meshes/front_left_wheel_1.stl" scale="0.001 0.001 0.001"/>
    </geometry>
    <material name="silver"/>
  </visual>
  <collision>
    <origin xyz="-0.145 -0.17 -0.0625" rpy="0 0 0"/>
    <geometry>
      <mesh filename="package://mobile_description/meshes/front_left_wheel_1.stl" scale="0.001 0.001 0.001"/>
    </geometry>
  </collision>
</link>

<link name="rear_left_wheel_1">
  <inertial>
    <origin xyz="-5.551115123125783e-17 0.019999999999999962 0.0" rpy="0 0 0"/>
    <mass value="3.8533597391687295"/>
    <inertia ixx="0.004277" iyy="0.007526" izz="0.004277" ixy="-0.0" iyz="-0.0" ixz="-0.0"/>
  </inertial>
  <visual>
    <origin xyz="0.145 -0.17 -0.0625" rpy="0 0 0"/>
    <geometry>
      <mesh filename="package://mobile_description/meshes/rear_left_wheel_1.stl" scale="0.001 0.001 0.001"/>
    </geometry>
    <material name="silver"/>
  </visual>
  <collision>
    <origin xyz="0.145 -0.17 -0.0625" rpy="0 0 0"/>
    <geometry>
      <mesh filename="package://mobile_description/meshes/rear_left_wheel_1.stl" scale="0.001 0.001 0.001"/>
    </geometry>
  </collision>
</link>

<link name="lidar_1">
  <inertial>
    <origin xyz="-9.4946098205817e-10 6.800340879809758e-16 0.019779238971984525" rpy="0 0 0"/>
    <mass value="1.1942370825491377"/>
    <inertia ixx="0.000518" iyy="0.000518" izz="0.000724" ixy="-0.0" iyz="-0.0" ixz="-0.0"/>
  </inertial>
  <visual>
    <origin xyz="-0.205 -0.0 -0.3275" rpy="0 0 0"/>
    <geometry>
      <mesh filename="package://mobile_description/meshes/lidar_1.stl" scale="0.001 0.001 0.001"/>
    </geometry>
    <material name="silver"/>
  </visual>
  <collision>
    <origin xyz="-0.205 -0.0 -0.3275" rpy="0 0 0"/>
    <geometry>
      <mesh filename="package://mobile_description/meshes/lidar_1.stl" scale="0.001 0.001 0.001"/>
    </geometry>
  </collision>
</link>

<link name="imu_1">
  <inertial>
    <origin xyz="0.0 0.0 0.0050000000000000044" rpy="0 0 0"/>
    <mass value="0.07064999999999999"/>
    <inertia ixx="6e-06" iyy="6e-06" izz="1.1e-05" ixy="0.0" iyz="0.0" ixz="0.0"/>
  </inertial>
  <visual>
    <origin xyz="-0.0 -0.0 -0.3275" rpy="0 0 0"/>
    <geometry>
      <mesh filename="package://mobile_description/meshes/imu_1.stl" scale="0.001 0.001 0.001"/>
    </geometry>
    <material name="silver"/>
  </visual>
  <collision>
    <origin xyz="-0.0 -0.0 -0.3275" rpy="0 0 0"/>
    <geometry>
      <mesh filename="package://mobile_description/meshes/imu_1.stl" scale="0.001 0.001 0.001"/>
    </geometry>
  </collision>
</link>

<joint name="Revolute 1" type="continuous">
  <origin xyz="-0.145 -0.17 0.0625" rpy="0 0 0"/>
  <parent link="base_link"/>
  <child link="rear_right_wheel_1"/>
  <axis xyz="0.0 -1.0 0.0"/>
</joint>

<joint name="Revolute 2" type="continuous">
  <origin xyz="0.145 -0.17 0.0625" rpy="0 0 0"/>
  <parent link="base_link"/>
  <child link="front_right_wheel_1"/>
  <axis xyz="0.0 -1.0 0.0"/>
</joint>

<joint name="Revolute 3" type="continuous"
  <origin xyz="0.145 0.17 0.0625" rpy="0 0 0"/>
  <parent link="base_link"/>
  <child link="front_left_wheel_1"/>
  <axis xyz="0.0 1.0 0.0"/>
</joint>

<joint name="Revolute 4" type="continuous">
  <origin xyz="-0.145 0.17 0.0625" rpy="0 0 0"/>
  <parent link="base_link"/>
  <child link="rear_left_wheel_1"/>
  <axis xyz="0.0 1.0 0.0"/>
</joint>

<joint name="Rigid 5" type="fixed">
  <origin xyz="0.205 0.0 0.3275" rpy="0 0 0"/>
  <parent link="base_link"/>
  <child link="lidar_1"/>
</joint>

<joint name="Rigid 6" type="fixed">
  <origin xyz="0.0 0.0 0.3275" rpy="0 0 0"/>
  <parent link="base_link"/>
  <child link="imu_1"/>
</joint>

</robot>
